<?xml version="1.0"?>
<robot xmlns:xacro="http://www.ros.org/wiki/xacro">

      <xacro:include filename="inertial_macros.xacro" />
      <!-- Base link -->

      <link name="base_link">

      </link>

      <!-- Chassis link -->

      <joint name="chassis_joint" type="fixed">
        <parent link="base_link"/>
        <child link="chassis"/>
        <origin xyz="-0.1 0 0"/>
      </joint>

      <link name="chassis">
         <visual>
            <origin xyz="0.15 0 0.075"/>
            <geometry>
               <box size="0.65 0.65 0.213"/>
            </geometry>
            <material name="chassis_material">
               <color rgba="0.573 0.239 0.254 1.0"/>
            </material>
         </visual>
         <collision>
            <origin xyz="0.15 0 0.075"/>
            <geometry>
               <box size="0.65 0.65 0.213"/>
            </geometry>
         </collision>
         <xacro:inertial_box mass="0.9" x="0.65" y="0.65" z="0.213">
            <origin xyz="0.15 0 0.075" rpy="0 0 0"/>
         </xacro:inertial_box>
      </link>

      <!-- Left wheel link -->
      <joint name="left_wheel_joint" type="continuous">
        <parent link="base_link"/>
        <child link="left_wheel"/>
        <origin xyz="0.2 0.353 0.048" rpy="-${pi/2} 0 0"/>
        <axis xyz="0 0 1"/>
      </joint>

      <link name="left_wheel">
         <visual>
            <geometry>
               <cylinder radius="0.173" length="0.04"/>
            </geometry>
            <material name="wheel_material">
               <color rgba="0.239 0.239 0.239 1.0"/>
            </material>
         </visual>
         <collision>
            <geometry>
               <cylinder radius="0.173" length="0.04"/>
            </geometry>
         </collision>
         <xacro:inertial_cylinder mass="0.2" length="0.04" radius="0.173">
            <origin xyz="0 0 0" rpy="0 0 0"/>
         </xacro:inertial_cylinder>
      </link>

      <!-- Right wheel link -->
      <joint name="right_wheel_joint" type="continuous">
        <parent link="base_link"/>
        <child link="right_wheel"/>
        <origin xyz="0.2 -0.353 0.048" rpy="${pi/2} 0 0"/>
        <axis xyz="0 0 -1"/>
      </joint>

      <link name="right_wheel">
         <visual>
            <geometry>
               <cylinder radius="0.173" length="0.04"/>
            </geometry>
            <material name="wheel_material">
                <color rgba="0.239 0.239 0.239 1.0"/>
            </material>
         </visual>
         <collision>
            <geometry>
               <cylinder radius="0.173" length="0.04"/>
            </geometry>
         </collision>
            <xacro:inertial_cylinder mass="0.2" length="0.04" radius="0.173">
            <origin xyz="0 0 0" rpy="0 0 0"/>
         </xacro:inertial_cylinder>
      </link>

      <!-- Castor wheel link -->
      <joint name="castor_wheel_joint" type="fixed">
        <parent link="chassis"/>
        <child link="castor_wheel"/>
        <origin xyz="-0.08 0 -0.048"/>
      </joint>

      <link name="castor_wheel">
         <visual>
            <geometry>
               <sphere radius="0.08"/>
            </geometry>
            <material name="castor_material">
                <color rgba="0.62 0.62 0.62 1.0"/>
            </material>
         </visual>
         <collision>
            <geometry>
               <sphere radius="0.08"/>
            </geometry>
         </collision>
         <xacro:inertial_sphere mass="0.15" radius="0.08">
            <origin xyz="0 0 0" rpy="0 0 0"/>
         </xacro:inertial_sphere>
      </link>

      <!-- Gazebo Parameters -->
      <gazebo reference="chassis_link">
         <mu1>1.0</mu1>
         <mu2>1.0</mu2>
      </gazebo>

      <gazebo reference="right_wheel">
         <mu1>1.0</mu1>
         <mu2>1.0</mu2>
      </gazebo>

      <gazebo reference="left_wheel">
         <mu1>1.0</mu1>
         <mu2>1.0</mu2>
      </gazebo>

      <gazebo reference="castor_wheel">
         <mu1>0.000001</mu1>
         <mu2>0.000001</mu2>
      </gazebo>

</robot>